Workbook

Sheet Cover
B3: Chipotle Mexican Grill, Inc. (NYSE: CMG)
B4: Comparable Companies Analysis (Trading Comps)
B6: PRIVATE & CONFIDENTIAL — FOR DISCUSSION PURPOSES ONLY
B9: Prepared for: | C9: Analyst Training / Portfolio Project
B10: Prepared by: | C10: Investment Banking Valuation Group
B11: Date: | C11: August 20, 2026
B12: Ticker / Exchange: | C12: CMG / NYSE
B13: Sector: | C13: Consumer Discretionary — Restaurants (Fast-Casual)
B15: Contents: Company Overview | Peer Selection | Raw Financial Data | Valuation Multiples | Trading Comps & Valuation | Football Field | Sensitivity | Dashboard
B17: Data sourcing note: figures in this workbook were compiled from public sources (company filings, earnings releases, and financial data aggregators) as of August 2026 for training/portfolio purposes. In live deal work, all comp data would be pulled from a single terminal (Capital IQ or FactSet) on one snapshot date to ensure consistent accounting treatment across peers. Where source data conflicted, the most internally consistent figures were used and flagged in cell comments. This workbook is illustrative and not a solicitation, recommendation, or offer to buy or sell any security.

Sheet Company Overview
A1: Company Overview — Chipotle Mexican Grill (CMG)
A2: Part 1: Business, Industry & Investment Thesis
B4: Key Market Statistics (as of Aug 20, 2026)
B5: Share Price | C5: 34.33
B6: 52-Week Range | C6: $28.04-$43.99
B7: Shares Outstanding (M) | C7: 1280
B8: Market Capitalization ($M) | C8: =C5*C7 -> 43942.4
B9: Avg. Analyst Price Target | C9: 43.8
B10: Analyst Consensus | C10: Buy (25B/0S)
B11: Next Earnings Date | C11: Oct 28, 2026
B13: Business Overview
B14: Business Model | C14: Predominantly company-operated fast-casual restaurant chain (vs. franchise-royalty peers). ~3,983 US locations, ~104 international units, ~14 licensed Middle East stores (YE 2025).
B15: Revenue Streams | C15: In-restaurant food & beverage (~62% of rev.), digital/delivery sales (38.3% of Q2'26 revenue), supplemented by catering.
B16: Geographic Exposure | C16: ~97%+ US-concentrated; early-stage international expansion (Canada, UK, France, Germany, and new Middle East licensing incl. first Saudi Arabia unit, opened Aug 2026).
B17: Products | C17: Burritos, bowls, quesadillas, tacos, salads — narrow menu, 'Responsibly Raised' ingredient positioning.
B18: Growth Drivers | C18: 350-370 new restaurants planned FY26 (80% w/ Chipotlanes); digital/loyalty penetration; HEAP kitchen automation rollout across 2,000 locations; international licensing optionality.
B19: Competition | C19: Fast-casual: CAVA, Sweetgreen, Shake Shack, Dutch Bros. Large-cap QSR: McDonald's, Yum! Brands, Domino's, RBI.
B20: Key Market Risks | C20: Recurring food-safety incidents (2026 salmonella/jalapeno outbreak, cyclospora headwind); consumer discretionary sensitivity; restaurant-level margin pressure (-220bps YoY in Q2'26); active securities litigation; premium multiple vulnerable to growth deceleration.
B21: Macro Factors | C21: Consumer discretionary spending cycle; beef/protein input cost inflation; CA-heavy labor cost exposure; interest-rate environment (WACC/financing).
B22: Investment Thesis | C22: Scaled, high-ROIC growth compounder with long unit-growth runway, trading well off its highs on transient food-safety-driven sentiment. Central valuation question: is the pullback to ~$34 pricing in a genuine reset of the growth/margin trajectory, or a temporary dislocation from a recoverable event?
B24: Source: Company filings (10-Q, 8-K), earnings call transcripts, and public market data as of Aug 2026 (see Part 1 research memo).

Sheet Peer Selection
A1: Peer Selection
A2: Part 2: Core vs. Reference Tier Comp Set & Rationale
B4: CORE TIER — Fast-Casual, Predominantly Company-Operated (drives primary valuation)
B5: Company | C5: Ticker | D5: Tier | E5: Rationale / Key Differences
B6: CAVA Group | C6: CAVA | D6: Core | E6: Closest structural analog: Mediterranean bowl format, company-operated, digital-forward. Much smaller scale, faster unit growth off small base.
B7: Sweetgreen | C7: SG | D7: Core | E7: Fast-casual healthy format, company-operated, digital-heavy. Weak same-store sales and unit economics; flagged as a statistical outlier candidate (near-zero/negative EBITDA).
B8: Shake Shack | C8: SHAK | D8: Core | E8: Fast-casual, significant company-operated base, premium positioning. Different product category (burgers); rich P/E partly driven by activist involvement (Starboard).
B9: Dutch Bros | C9: BROS | D9: Core | E9: Fast-growing, drive-thru-led format directly analogous to CMG's Chipotlane strategy. Beverage category; partial franchise mix.
B10: Wingstop | C10: WING | D10: Core* | E10: *95-99% franchised — margin structure closer to Reference tier. Included for growth-multiple context; EXCLUDED from primary EV/EBITDA valuation range (see Trading Comps tab).
B12: REFERENCE TIER — Large-Cap, Predominantly Franchised QSR (context only)
B13: McDonald's | C13: MCD | D13: Reference | E13: World's largest restaurant chain by market cap. Asset-light franchise model (~93% franchised) — margin gap vs. CMG is structural, not a performance signal.
B14: Yum! Brands | C14: YUM | D14: Reference | E14: KFC/Taco Bell/Pizza Hut/Habit Burger. DILIGENCE FLAG: actively divesting Pizza Hut ($2.7B total); forward financials in transition as of Aug 2026.
B15: Domino's Pizza | C15: DPZ | D15: Reference | E15: US franchise model at a premium multiple; currently at decade-low valuation on flat US comps and GLP-1/weight-loss-drug demand concerns.
B16: Restaurant Brands Int'l | C16: QSR | D16: Reference | E16: Burger King/Tim Hortons/Popeyes/Firehouse Subs. Hybrid company/franchise model — the 'closest comparable' among large hybrid peers per sell-side research.
B17: Starbucks | C17: SBUX | D17: Reference | E17: Global scaled digital/loyalty ecosystem, drive-thru relevance. Currently mid-turnaround — trades at growth-name multiples despite mature scale; treat narrative-adjusted.
B19: Size / Growth / Margin / Geography / Capital Intensity Summary
B20: Size | C20: Core: $2B-$13B mkt cap. Reference: $25B-$195B mkt cap.
B21: Growth | C21: Core: 9%-32% revenue growth. Reference: low-to-mid single digits.
B22: Margins | C22: Core: 25-30% restaurant-level margin, thinner corporate margin. Reference: 35-45% operating margin (franchise royalty economics).
B23: Geography | C23: Core: ~95%+ US-concentrated. Reference: majority international (MCD, YUM especially).
B24: Business Mix | C24: Core: predominantly company-operated. Reference: predominantly franchised/asset-light.
B25: Capital Intensity | C25: Core: high (new-unit buildout, kitchen equipment capex). Reference: low (franchisees bear buildout capex).

Sheet Raw Data
A1: Raw Financial Data — Core Peer Tier
A2: Part 3: All $ in millions except per-share and % figures. TTM basis, as of Aug 2026.
B4: Company | C4: Ticker | D4: Price | E4: Shares (M) | F4: Mkt Cap | G4: Cash | H4: Debt | I4: EV | J4: Revenue | K4: EBITDA | L4: EBIT | M4: Net Income | N4: EPS | O4: ROE | P4: ROIC | Q4: Fwd EPS Gr.
B5: Chipotle Mexican Grill | C5: CMG | D5: 34.33 | E5: 1280 | F5: =D5*E5 -> 43942.4 | G5: 871 | H5: 5250 | I5: =F5-G5+H5 -> 48321.4 | J5: 12140 | K5: 2500 | L5: 1890 | M5: 1450 | N5: 1.09 | O5: 0.492 | P5: 0.215 | Q5: 0.094
B6: CAVA Group | C6: CAVA | D6: 66 | E6: 116.4 | F6: =D6*E6 -> 7682.4 | G6: 403 | H6: 498 | I6: =F6-G6+H6 -> 7777.4 | J6: 1290 | K6: 146 | L6: 60 | M6: 62 | N6: 0.53 | O6: 0.08 | P6: 0.062 | Q6: 0.25
B7: Sweetgreen | C7: SG | D7: 8 | E7: 112 | F7: =D7*E7 -> 896 | G7: 157 | H7: 356 | I7: =F7-G7+H7 -> 1095 | J7: 685 | K7: -10 | L7: -96 | M7: -45 | N7: -0.4 | O7: -0.08 | P7: -0.15 | Q7: n.m.
B8: Shake Shack | C8: SHAK | D8: 91 | E8: 43 | F8: =D8*E8 -> 3913 | G8: 308 | H8: 952 | I8: =F8-G8+H8 -> 4557 | J8: 1550 | K8: 472 | L8: 200 | M8: 40 | N8: 0.95 | O8: 0.079 | P8: 0.033 | Q8: 0.25
B9: Dutch Bros | C9: BROS | D9: 53 | E9: 188.4 | F9: =D9*E9 -> 9985.2 | G9: 250 | H9: 600 | I9: =F9-G9+H9 -> 10335.2 | J9: 1880 | K9: 318 | L9: 200 | M9: 92 | N9: 0.49 | O9: 0.146 | P9: 0.084 | Q9: 0.4
B10: Wingstop | C10: WING | D10: 254.2 | E10: 27.5 | F10: =D10*E10 -> 6990.5 | G10: 197 | H10: 1270 | I10: =F10-G10+H10 -> 8063.5 | J10: 697 | K10: 216 | L10: 190 | M10: 174 | N10: 6.21 | O10: 0.45 | P10: 0.2 | Q10: -0.1
B12: Blue = hardcoded input (compiled from public filings/market data, Aug 2026 pull; see Parts 1-3 memo for sourcing detail). Black = formula. Wingstop ROE/ROIC/cash/debt are estimates (marked for CapIQ verification in live practice).
B13: Sweetgreen: EBITDA/EBIT/NI shown as negative — TTM figures were near-breakeven/negative across multiple data vendors; excluded from EV/EBITDA statistics on Trading Comps tab as not meaningful (n.m.).
B15: Reference Tier — Multiples-Only Summary (context; excluded from primary valuation math)
B16: Company | C16: Ticker | D16: Mkt Cap | E16: EV/EBITDA | F16: P/E
B17: McDonald's | C17: MCD | D17: 193000 | E17: 17 | F17: 24
B18: Yum! Brands | C18: YUM | D18: 41000 | E18: 16 | F18: 22
B19: Domino's Pizza | C19: DPZ | D19: 14000 | E19: 18 | F19: 23
B20: Restaurant Brands Int'l | C20: QSR | D20: 25300 | E20: 13 | F20: 18
B21: Starbucks | C21: SBUX | D21: 122300 | E21: 26.9 | F21: 81.9
B23: Reference tier carries multiples only (no EV/cash/debt detail) per project scope decision — see Part 2/3 memo.

Sheet Multiples
A1: Valuation Multiples — Core Peer Tier
A2: Part 4: EV/Revenue, EV/EBITDA, EV/EBIT, P/E, P/B, P/S, PEG (all formula-linked to Raw Data)
B4: Company | C4: Ticker | D4: EV/Revenue | E4: EV/EBITDA | F4: EV/EBIT | G4: P/E (TTM) | H4: Fwd P/E | I4: P/B | J4: P/S | K4: PEG
B5: ='Raw Data'!B5 -> Chipotle Mexican Grill | C5: ='Raw Data'!C5 -> CMG | D5: ='Raw Data'!I5/'Raw Data'!J5 -> 3.980346 | E5: =IF('Raw Data'!K5<=0,"n.m.",'Raw Data'!I5/'Raw Data'!K5) -> 19.32856 | F5: =IF('Raw Data'!L5<=0,"n.m.",'Raw Data'!I5/'Raw Data'!L5) -> 25.566878 | G5: =IF('Raw Data'!N5<=0,"n.m.",'Raw Data'!D5/'Raw Data'!N5) -> 31.495413 | H5: =IF(OR('Raw Data'!N5<=0,'Raw Data'!Q5="n.m."),"n.m.",G5/(1+'Raw Data'!Q5)) -> 28.789226 | I5: =IF('Raw Data'!O5<=0,"n.m.",'Raw Data'!F5/('Raw Data'!M5/'Raw Data'!O5)) -> 14.910111 | J5: ='Raw Data'!F5/'Raw Data'!J5 -> 3.6196376 | K5: =IF(OR('Raw Data'!Q5="n.m.",'Raw Data'!Q5<=0,G5="n.m."),"n.m.",G5/('Raw Data'!Q5*100)) -> 3.3505758
B6: ='Raw Data'!B6 -> CAVA Group | C6: ='Raw Data'!C6 -> CAVA | D6: ='Raw Data'!I6/'Raw Data'!J6 -> 6.0289922 | E6: =IF('Raw Data'!K6<=0,"n.m.",'Raw Data'!I6/'Raw Data'!K6) -> 53.269863 | F6: =IF('Raw Data'!L6<=0,"n.m.",'Raw Data'!I6/'Raw Data'!L6) -> 129.62333 | G6: =IF('Raw Data'!N6<=0,"n.m.",'Raw Data'!D6/'Raw Data'!N6) -> 124.5283 | H6: =IF(OR('Raw Data'!N6<=0,'Raw Data'!Q6="n.m."),"n.m.",G6/(1+'Raw Data'!Q6)) -> 99.622642 | I6: =IF('Raw Data'!O6<=0,"n.m.",'Raw Data'!F6/('Raw Data'!M6/'Raw Data'!O6)) -> 9.9127742 | J6: ='Raw Data'!F6/'Raw Data'!J6 -> 5.9553488 | K6: =IF(OR('Raw Data'!Q6="n.m.",'Raw Data'!Q6<=0,G6="n.m."),"n.m.",G6/('Raw Data'!Q6*100)) -> 4.9811321
B7: ='Raw Data'!B7 -> Sweetgreen | C7: ='Raw Data'!C7 -> SG | D7: ='Raw Data'!I7/'Raw Data'!J7 -> 1.5985401 | E7: =IF('Raw Data'!K7<=0,"n.m.",'Raw Data'!I7/'Raw Data'!K7) -> n.m. | F7: =IF('Raw Data'!L7<=0,"n.m.",'Raw Data'!I7/'Raw Data'!L7) -> n.m. | G7: =IF('Raw Data'!N7<=0,"n.m.",'Raw Data'!D7/'Raw Data'!N7) -> n.m. | H7: =IF(OR('Raw Data'!N7<=0,'Raw Data'!Q7="n.m."),"n.m.",G7/(1+'Raw Data'!Q7)) -> n.m. | I7: =IF('Raw Data'!O7<=0,"n.m.",'Raw Data'!F7/('Raw Data'!M7/'Raw Data'!O7)) -> n.m. | J7: ='Raw Data'!F7/'Raw Data'!J7 -> 1.3080292 | K7: =IF(OR('Raw Data'!Q7="n.m.",'Raw Data'!Q7<=0,G7="n.m."),"n.m.",G7/('Raw Data'!Q7*100)) -> n.m.
B8: ='Raw Data'!B8 -> Shake Shack | C8: ='Raw Data'!C8 -> SHAK | D8: ='Raw Data'!I8/'Raw Data'!J8 -> 2.94 | E8: =IF('Raw Data'!K8<=0,"n.m.",'Raw Data'!I8/'Raw Data'!K8) -> 9.654661 | F8: =IF('Raw Data'!L8<=0,"n.m.",'Raw Data'!I8/'Raw Data'!L8) -> 22.785 | G8: =IF('Raw Data'!N8<=0,"n.m.",'Raw Data'!D8/'Raw Data'!N8) -> 95.789474 | H8: =IF(OR('Raw Data'!N8<=0,'Raw Data'!Q8="n.m."),"n.m.",G8/(1+'Raw Data'!Q8)) -> 76.631579 | I8: =IF('Raw Data'!O8<=0,"n.m.",'Raw Data'!F8/('Raw Data'!M8/'Raw Data'!O8)) -> 7.728175 | J8: ='Raw Data'!F8/'Raw Data'!J8 -> 2.5245161 | K8: =IF(OR('Raw Data'!Q8="n.m.",'Raw Data'!Q8<=0,G8="n.m."),"n.m.",G8/('Raw Data'!Q8*100)) -> 3.8315789
B9: ='Raw Data'!B9 -> Dutch Bros | C9: ='Raw Data'!C9 -> BROS | D9: ='Raw Data'!I9/'Raw Data'!J9 -> 5.4974468 | E9: =IF('Raw Data'!K9<=0,"n.m.",'Raw Data'!I9/'Raw Data'!K9) -> 32.500629 | F9: =IF('Raw Data'!L9<=0,"n.m.",'Raw Data'!I9/'Raw Data'!L9) -> 51.676 | G9: =IF('Raw Data'!N9<=0,"n.m.",'Raw Data'!D9/'Raw Data'!N9) -> 108.16327 | H9: =IF(OR('Raw Data'!N9<=0,'Raw Data'!Q9="n.m."),"n.m.",G9/(1+'Raw Data'!Q9)) -> 77.259475 | I9: =IF('Raw Data'!O9<=0,"n.m.",'Raw Data'!F9/('Raw Data'!M9/'Raw Data'!O9)) -> 15.846078 | J9: ='Raw Data'!F9/'Raw Data'!J9 -> 5.3112766 | K9: =IF(OR('Raw Data'!Q9="n.m.",'Raw Data'!Q9<=0,G9="n.m."),"n.m.",G9/('Raw Data'!Q9*100)) -> 2.7040816
B10: ='Raw Data'!B10 -> Wingstop | C10: ='Raw Data'!C10 -> WING | D10: ='Raw Data'!I10/'Raw Data'!J10 -> 11.568867 | E10: =IF('Raw Data'!K10<=0,"n.m.",'Raw Data'!I10/'Raw Data'!K10) -> 37.331019 | F10: =IF('Raw Data'!L10<=0,"n.m.",'Raw Data'!I10/'Raw Data'!L10) -> 42.439474 | G10: =IF('Raw Data'!N10<=0,"n.m.",'Raw Data'!D10/'Raw Data'!N10) -> 40.933977 | H10: =IF(OR('Raw Data'!N10<=0,'Raw Data'!Q10="n.m."),"n.m.",G10/(1+'Raw Data'!Q10)) -> 45.482197 | I10: =IF('Raw Data'!O10<=0,"n.m.",'Raw Data'!F10/('Raw Data'!M10/'Raw Data'!O10)) -> 18.078879 | J10: ='Raw Data'!F10/'Raw Data'!J10 -> 10.029412 | K10: =IF(OR('Raw Data'!Q10="n.m.",'Raw Data'!Q10<=0,G10="n.m."),"n.m.",G10/('Raw Data'!Q10*100)) -> n.m.
B12: All multiples are formula-linked to the Raw Data tab — changing an input there recalculates every multiple automatically.
B13: n.m. = not meaningful (negative or near-zero denominator, e.g. Sweetgreen's EBITDA/EBIT/EPS).

Sheet Trading Comps
A1: Trading Comps & Valuation
A2: Parts 5-6: Statistical Summary, Implied Valuation, DCF Cross-Check
B4: EV/EBITDA Statistics — Core Peers (CMG and Sweetgreen excluded from stats) | H4: Implied Valuation — Applied to CMG
B5: Company | C5: EV/EBITDA | H5: CMG TTM EBITDA ($M) | I5: ='Raw Data'!K5 -> 2500
B6: =Multiples!B6 -> CAVA Group | C6: =Multiples!E6 -> 53.269863 | H6: CMG TTM Revenue ($M) | I6: ='Raw Data'!J5 -> 12140
B7: =Multiples!B7 -> Sweetgreen | C7: =Multiples!E7 -> n.m. | H7: CMG Cash ($M) | I7: ='Raw Data'!G5 -> 871
B8: =Multiples!B8 -> Shake Shack | C8: =Multiples!E8 -> 9.654661 | H8: CMG Debt ($M) | I8: ='Raw Data'!H5 -> 5250
B9: =Multiples!B9 -> Dutch Bros | C9: =Multiples!E9 -> 32.500629 | H9: CMG Shares Outstanding (M) | I9: ='Raw Data'!E5 -> 1280
B10: =Multiples!B10 -> Wingstop | C10: =Multiples!E10 -> 37.331019 | H10: Current Share Price | I10: ='Raw Data'!D5 -> 34.33
B12: Mean | C12: =AVERAGE(C6:C10) -> 33.189043 | H12: Scenario B: Full-Set Median (x) | I12: =C13 -> 34.915824
B13: Median | C13: =MEDIAN(C6:C10) -> 34.915824 | H13: Scenario A: Ex-CAVA Median (x) | I13: =C24 -> 21.077645
B14: 25th Percentile | C14: =QUARTILE(C6:C10,1) -> 26.789137 | H14: EV/Revenue Median (x) | I14: =C34 -> 4.2187234
B15: 75th Percentile | C15: =QUARTILE(C6:C10,3) -> 41.31573
B16: Minimum | C16: =MIN(C6:C10) -> 9.654661 | H16: Scenario | I16: Implied Price
B17: Maximum | C17: =MAX(C6:C10) -> 53.269863 | H17: Scenario A (Ex-CAVA Median, EV/EBITDA) | I17: =((I13*I5)-I8+I7)/I9 -> 37.746182
B18: Standard Deviation | C18: =STDEV(C6:C10) -> 18.025319 | H18: Scenario B (Full-Set Median, EV/EBITDA) | I18: =((I12*I5)-I8+I7)/I9 -> 64.773874
H19: EV/Revenue Cross-Check | I19: =((I14*I6)-I8+I7)/I9 -> 36.590861
B20: Note: Sweetgreen shows 'n.m.' (text) in the EV/EBITDA column above — Excel's AVERAGE/MEDIAN/QUARTILE/STDEV functions
B21: automatically ignore text values, so it is excluded from these statistics without needing a separate range (see Part 5 memo). | H21: Implied Premium / (Discount) to Current Price
H22: Scenario A (Ex-CAVA Median, EV/EBITDA) | I22: =I17/I10-1 -> 0.099510096
B23: Scenario Median — Excluding CAVA (growth outlier, per Part 5 judgment call) | H23: Scenario B (Full-Set Median, EV/EBITDA) | I23: =I18/I10-1 -> 0.88680089
B24: Ex-CAVA Median EV/EBITDA (SHAK, BROS avg) | C24: =AVERAGE(Multiples!E8,Multiples!E9) -> 21.077645 | H24: EV/Revenue Cross-Check | I24: =I19/I10-1 -> 0.065856715
B25: Illustrative 2-name ex-CAVA average per Part 5 discussion; full ex-CAVA peer set would use SHAK+BROS+WING if WING were included.
B27: EV/Revenue Statistics — Core Peers incl. Sweetgreen (secondary cross-check)
B28: Company | C28: EV/Revenue
B29: =Multiples!B6 -> CAVA Group | C29: =Multiples!D6 -> 6.0289922
B30: =Multiples!B7 -> Sweetgreen | C30: =Multiples!D7 -> 1.5985401
B31: =Multiples!B8 -> Shake Shack | C31: =Multiples!D8 -> 2.94
B32: =Multiples!B9 -> Dutch Bros | C32: =Multiples!D9 -> 5.4974468
B34: Median EV/Revenue | C34: =MEDIAN(C29:C32) -> 4.2187234
B37: DCF Cross-Check — Simplified 5-Year Unlevered FCF (all $M unless noted)
B38: Assumptions:
B39: WACC | C39: 0.09
B40: Terminal Growth Rate | C40: 0.03
B41: Tax Rate | C41: 0.26
B42: Capex (% of Revenue) | C42: 0.08
B43: D&A (% of Revenue) | C43: 0.05
B44: NWC Drag ($M/yr) | C44: 50
B46: ($M) | D46: Y1 | E46: Y2 | F46: Y3 | G46: Y4 | H46: Y5
B47: Revenue Growth % | D47: 0.09 | E47: 0.08 | F47: 0.07 | G47: 0.06 | H47: 0.05
...

Sheet Sensitivity
A1: Sensitivity Analysis
A2: DCF Implied Share Price — WACC vs. Terminal Growth Rate
B4: Implied Share Price Grid ($) — each cell independently formula-derived from the DCF build
B6: WACC \ Term. Growth | C6: 0.025 | D6: 0.0275 | E6: 0.03 | F6: 0.0325 | G6: 0.035
B7: 0.08 | C7: =(SUMPRODUCT('Trading Comps'!D58:H58/(1+0.08)^'Trading Comps'!D59:H59)+('Trading Comps'!H58*(1+0.025)/(0.08-0.025))/(1+0.08)^5-'Raw Data'!H5+'Raw Data'!G5)/'Raw Data'!E5 -> 17.150126 | D7: =(SUMPRODUCT('Trading Comps'!D58:H58/(1+0.08)^'Trading Comps'!D59:H59)+('Trading Comps'!H58*(1+0.0275)/(0.08-0.0275))/(1+0.08)^5-'Raw Data'!H5+'Raw Data'!G5)/'Raw Data'!E5 -> 17.967213 | E7: =(SUMPRODUCT('Trading Comps'!D58:H58/(1+0.08)^'Trading Comps'!D59:H59)+('Trading Comps'!H58*(1+0.03)/(0.08-0.03))/(1+0.08)^5-'Raw Data'!H5+'Raw Data'!G5)/'Raw Data'!E5 -> 18.866008 | F7: =(SUMPRODUCT('Trading Comps'!D58:H58/(1+0.08)^'Trading Comps'!D59:H59)+('Trading Comps'!H58*(1+0.0325)/(0.08-0.0325))/(1+0.08)^5-'Raw Data'!H5+'Raw Data'!G5)/'Raw Data'!E5 -> 19.859413 | G7: =(SUMPRODUCT('Trading Comps'!D58:H58/(1+0.08)^'Trading Comps'!D59:H59)+('Trading Comps'!H58*(1+0.035)/(0.08-0.035))/(1+0.08)^5-'Raw Data'!H5+'Raw Data'!G5)/'Raw Data'!E5 -> 20.963197
B8: 0.085 | C8: =(SUMPRODUCT('Trading Comps'!D58:H58/(1+0.085)^'Trading Comps'!D59:H59)+('Trading Comps'!H58*(1+0.025)/(0.085-0.025))/(1+0.085)^5-'Raw Data'!H5+'Raw Data'!G5)/'Raw Data'!E5 -> 15.392632 | D8: =(SUMPRODUCT('Trading Comps'!D58:H58/(1+0.085)^'Trading Comps'!D59:H59)+('Trading Comps'!H58*(1+0.0275)/(0.085-0.0275))/(1+0.085)^5-'Raw Data'!H5+'Raw Data'!G5)/'Raw Data'!E5 -> 16.063979 | E8: =(SUMPRODUCT('Trading Comps'!D58:H58/(1+0.085)^'Trading Comps'!D59:H59)+('Trading Comps'!H58*(1+0.03)/(0.085-0.03))/(1+0.085)^5-'Raw Data'!H5+'Raw Data'!G5)/'Raw Data'!E5 -> 16.796357 | F8: =(SUMPRODUCT('Trading Comps'!D58:H58/(1+0.085)^'Trading Comps'!D59:H59)+('Trading Comps'!H58*(1+0.0325)/(0.085-0.0325))/(1+0.085)^5-'Raw Data'!H5+'Raw Data'!G5)/'Raw Data'!E5 -> 17.598486 | G8: =(SUMPRODUCT('Trading Comps'!D58:H58/(1+0.085)^'Trading Comps'!D59:H59)+('Trading Comps'!H58*(1+0.035)/(0.085-0.035))/(1+0.085)^5-'Raw Data'!H5+'Raw Data'!G5)/'Raw Data'!E5 -> 18.480828
B9: 0.09 | C9: =(SUMPRODUCT('Trading Comps'!D58:H58/(1+0.09)^'Trading Comps'!D59:H59)+('Trading Comps'!H58*(1+0.025)/(0.09-0.025))/(1+0.09)^5-'Raw Data'!H5+'Raw Data'!G5)/'Raw Data'!E5 -> 13.906201 | D9: =(SUMPRODUCT('Trading Comps'!D58:H58/(1+0.09)^'Trading Comps'!D59:H59)+('Trading Comps'!H58*(1+0.0275)/(0.09-0.0275))/(1+0.09)^5-'Raw Data'!H5+'Raw Data'!G5)/'Raw Data'!E5 -> 14.46594 | E9: =(SUMPRODUCT('Trading Comps'!D58:H58/(1+0.09)^'Trading Comps'!D59:H59)+('Trading Comps'!H58*(1+0.03)/(0.09-0.03))/(1+0.09)^5-'Raw Data'!H5+'Raw Data'!G5)/'Raw Data'!E5 -> 15.072324 | F9: =(SUMPRODUCT('Trading Comps'!D58:H58/(1+0.09)^'Trading Comps'!D59:H59)+('Trading Comps'!H58*(1+0.0325)/(0.09-0.0325))/(1+0.09)^5-'Raw Data'!H5+'Raw Data'!G5)/'Raw Data'!E5 -> 15.731438 | G9: =(SUMPRODUCT('Trading Comps'!D58:H58/(1+0.09)^'Trading Comps'!D59:H59)+('Trading Comps'!H58*(1+0.035)/(0.09-0.035))/(1+0.09)^5-'Raw Data'!H5+'Raw Data'!G5)/'Raw Data'!E5 -> 16.45047
B10: 0.095 | C10: =(SUMPRODUCT('Trading Comps'!D58:H58/(1+0.095)^'Trading Comps'!D59:H59)+('Trading Comps'!H58*(1+0.025)/(0.095-0.025))/(1+0.095)^5-'Raw Data'!H5+'Raw Data'!G5)/'Raw Data'!E5 -> 12.632735 | D10: =(SUMPRODUCT('Trading Comps'!D58:H58/(1+0.095)^'Trading Comps'!D59:H59)+('Trading Comps'!H58*(1+0.0275)/(0.095-0.0275))/(1+0.095)^5-'Raw Data'!H5+'Raw Data'!G5)/'Raw Data'!E5 -> 13.105263 | E10: =(SUMPRODUCT('Trading Comps'!D58:H58/(1+0.095)^'Trading Comps'!D59:H59)+('Trading Comps'!H58*(1+0.03)/(0.095-0.03))/(1+0.095)^5-'Raw Data'!H5+'Raw Data'!G5)/'Raw Data'!E5 -> 13.614138 | F10: =(SUMPRODUCT('Trading Comps'!D58:H58/(1+0.095)^'Trading Comps'!D59:H59)+('Trading Comps'!H58*(1+0.0325)/(0.095-0.0325))/(1+0.095)^5-'Raw Data'!H5+'Raw Data'!G5)/'Raw Data'!E5 -> 14.163723 | G10: =(SUMPRODUCT('Trading Comps'!D58:H58/(1+0.095)^'Trading Comps'!D59:H59)+('Trading Comps'!H58*(1+0.035)/(0.095-0.035))/(1+0.095)^5-'Raw Data'!H5+'Raw Data'!G5)/'Raw Data'!E5 -> 14.759108
B11: 0.1 | C11: =(SUMPRODUCT('Trading Comps'!D58:H58/(1+0.1)^'Trading Comps'!D59:H59)+('Trading Comps'!H58*(1+0.025)/(0.1-0.025))/(1+0.1)^5-'Raw Data'!H5+'Raw Data'!G5)/'Raw Data'!E5 -> 11.529628 | D11: =(SUMPRODUCT('Trading Comps'!D58:H58/(1+0.1)^'Trading Comps'!D59:H59)+('Trading Comps'!H58*(1+0.0275)/(0.1-0.0275))/(1+0.1)^5-'Raw Data'!H5+'Raw Data'!G5)/'Raw Data'!E5 -> 11.932823 | E11: =(SUMPRODUCT('Trading Comps'!D58:H58/(1+0.1)^'Trading Comps'!D59:H59)+('Trading Comps'!H58*(1+0.03)/(0.1-0.03))/(1+0.1)^5-'Raw Data'!H5+'Raw Data'!G5)/'Raw Data'!E5 -> 12.364818 | F11: =(SUMPRODUCT('Trading Comps'!D58:H58/(1+0.1)^'Trading Comps'!D59:H59)+('Trading Comps'!H58*(1+0.0325)/(0.1-0.0325))/(1+0.1)^5-'Raw Data'!H5+'Raw Data'!G5)/'Raw Data'!E5 -> 12.828812 | G11: =(SUMPRODUCT('Trading Comps'!D58:H58/(1+0.1)^'Trading Comps'!D59:H59)+('Trading Comps'!H58*(1+0.035)/(0.1-0.035))/(1+0.1)^5-'Raw Data'!H5+'Raw Data'!G5)/'Raw Data'!E5 -> 13.328498
B14: Yellow cell = base-case assumption (9.0% WACC / 3.0% terminal growth), matching the Trading Comps DCF build.
B15: Each grid cell independently discounts the same 5-year unlevered FCF stream from the Trading Comps tab at the row's WACC
B16: and column's terminal growth rate — changing the DCF assumptions on Trading Comps flows through to every cell here automatically.
B19: Key Takeaway
B20: Even at the most favorable corner of this grid (8.0% WACC / 3.5% terminal growth), the DCF implied price remains well below the comps-implied range of $41-$65, reinforcing that the valuation gap identified in Part 6 is driven by structural modeling assumptions (capex intensity held flat) rather than by a narrow, easily-resolved discount-rate debate.

Sheet Football Field
A1: Football Field Valuation
A2: Part 8: Valuation Range Summary Across Methodologies
B4: Valuation Range Data (Low / High, $ per share)
B5: Methodology | C5: Low | D5: High | E5: Range (High-Low)
B6: 52-Week Trading Range | C6: 28.04 | D6: 43.99 | E6: =D6-C6 -> 15.95
B7: Historical Trading Range (1-Yr Avg +/-10%) | C7: 30.9 | D7: 37.76 | E7: =D7-C7 -> 6.86
B8: DCF Valuation (Sensitivity Grid) | C8: 9.6 | D8: 25.15 | E8: =D8-C8 -> 15.55
B9: Comparable Companies (Core Peer EV/EBITDA) | C9: =MIN('Trading Comps'!I17,'Trading Comps'!I18,'Trading Comps'!I19) -> 36.590861 | D9: =MAX('Trading Comps'!I17,'Trading Comps'!I18,'Trading Comps'!I19) -> 64.773874 | E9: =D9-C9 -> 28.183013
B10: Analyst Price Targets (Low/High) | C10: 32 | D10: 55 | E10: =D10-C10 -> 23
B11: Current Share Price (point marker) | C11: ='Raw Data'!D5 -> 34.33 | D11: ='Raw Data'!D5 -> 34.33 | E11: =D11-C11 -> 0
B13: Chart below uses a stacked-bar technique: an invisible base series (= Low) plus a visible series (= High-Low range),
B14: the standard method for building football-field bar charts in Excel. Current price is overlaid as a single-point marker.

Sheet Dashboard
B2: CMG Trading Comps — Executive Dashboard
B3: Comparable Companies Analysis | Prepared Aug 2026
B5: Current Price | C5: Recommended Target Range | D5: Implied Upside (midpoint) | F5: Analyst Consensus | G5: Avg. Analyst Target
B6: ='Raw Data'!D5 -> 34.33 | C6: $37 - $45 | D6: =(41/'Raw Data'!D5)-1 -> 0.19429071 | F6: Buy | G6: 43.8
B9: EV/EBITDA — CMG vs. Core Peer Set
B10: Company | C10: EV/EBITDA
B11: =Multiples!B5 -> Chipotle Mexican Grill | C11: =IF(Multiples!E5="n.m.",0,Multiples!E5) -> 19.32856
B12: =Multiples!B6 -> CAVA Group | C12: =IF(Multiples!E6="n.m.",0,Multiples!E6) -> 53.269863
B13: =Multiples!B7 -> Sweetgreen | C13: =IF(Multiples!E7="n.m.",0,Multiples!E7) -> 0
B14: =Multiples!B8 -> Shake Shack | C14: =IF(Multiples!E8="n.m.",0,Multiples!E8) -> 9.654661
B15: =Multiples!B9 -> Dutch Bros | C15: =IF(Multiples!E9="n.m.",0,Multiples!E9) -> 32.500629
B16: =Multiples!B10 -> Wingstop | C16: =IF(Multiples!E10="n.m.",0,Multiples!E10) -> 37.331019
B32: Investment Recommendation Summary
B33: CMG trades at a premium EV/EBITDA multiple (19.2x) above the low end of its Core fast-casual peer set but well below the peer median (~34.9x) once high-growth outlier CAVA is included. Superior ROE (49.2%) and ROIC (21.5%) relative to every Core peer support a premium valuation. Current price reflects a discount tied to transient food-safety headlines (2026 salmonella/cyclospora incidents) and decelerating comps rather than a structural deterioration in unit economics. Recommended target range: $37-$45, implying roughly 8%-30% upside — consistent with Buy-side analyst consensus ($43.80 average target). Key risk: recurrence or escalation of food-safety issues could further compress the multiple and validate the more conservative DCF-implied valuation instead.
